{"uuid": "e9dcad22-e6a6-40d1-a9ee-1bbf83133821", "children": ["93ee2765-32eb-4ec7-bdd9-7691201dc3cb", "a523dec4-0d39-467c-b939-12e3dd9801d7", "a18451a0-c86b-4a44-b471-cd7cfff54ec0", "028d6ecc-d4b8-48dd-9bc0-07ebeaa2ddc7", "d4ff65ea-47ab-429e-9d28-5320cee86a73"], "befores": [{"name": "_Class__pytest_setup_class", "status": "broken", "statusDetails": {"message": "requests.exceptions.ConnectionError: HTTPConnectionPool(host='127.0.0,.1', port=8001): Max retries exceeded with url: /uc/v1/login/local?appId=10001&openId=7282 (Caused by NewConnectionError('<urllib3.connection.HTTPConnection object at 0x10dc3b1c0>: Failed to establish a new connection: [Errno 8] nodename nor servname provided, or not known'))\n", "trace": "  File \"/Library/Frameworks/Python.framework/Versions/3.9/lib/python3.9/site-packages/pluggy/callers.py\", line 187, in _multicall\n    res = hook_impl.function(*args)\n  File \"/Library/Frameworks/Python.framework/Versions/3.9/lib/python3.9/site-packages/_pytest/fixtures.py\", line 964, in pytest_fixture_setup\n    result = call_fixture_func(fixturefunc, request, kwargs)\n  File \"/Library/Frameworks/Python.framework/Versions/3.9/lib/python3.9/site-packages/_pytest/fixtures.py\", line 788, in call_fixture_func\n    res = next(it)\n  File \"/Library/Frameworks/Python.framework/Versions/3.9/lib/python3.9/site-packages/_pytest/python.py\", line 701, in xunit_setup_class_fixture\n    _call_with_optional_argument(func, self.obj)\n  File \"/Library/Frameworks/Python.framework/Versions/3.9/lib/python3.9/site-packages/_pytest/python.py\", line 632, in _call_with_optional_argument\n    func(arg)\n  File \"/Users/xhong/Documents/xiehong/Api_Autotest/testcase/test_refreshToken.py\", line 27, in setup_class\n    res = request.get(url=url, params=data)\n  File \"/Users/xhong/Documents/xiehong/Api_Autotest/utils/RequestsUtil.py\", line 56, in get\n    return self.requests_api(url, method=\"get\", **kwargs)\n  File \"/Users/xhong/Documents/xiehong/Api_Autotest/utils/RequestsUtil.py\", line 39, in requests_api\n    res = requests.get(url, json=json, params=params, headers=headers, cookies=cookies)\n  File \"/Library/Frameworks/Python.framework/Versions/3.9/lib/python3.9/site-packages/requests/api.py\", line 76, in get\n    return request('get', url, params=params, **kwargs)\n  File \"/Library/Frameworks/Python.framework/Versions/3.9/lib/python3.9/site-packages/requests/api.py\", line 61, in request\n    return session.request(method=method, url=url, **kwargs)\n  File \"/Library/Frameworks/Python.framework/Versions/3.9/lib/python3.9/site-packages/requests/sessions.py\", line 542, in request\n    resp = self.send(prep, **send_kwargs)\n  File \"/Library/Frameworks/Python.framework/Versions/3.9/lib/python3.9/site-packages/requests/sessions.py\", line 655, in send\n    r = adapter.send(request, **kwargs)\n  File \"/Library/Frameworks/Python.framework/Versions/3.9/lib/python3.9/site-packages/requests/adapters.py\", line 516, in send\n    raise ConnectionError(e, request=request)\n"}, "start": 1622604548026, "stop": 1622604548032}], "start": 1622604548026, "stop": 1622604548859}